2025-05-02 23:00:14,393 INFO    MainThread:95126 [wandb_setup.py:_flush():68] Current SDK version is 0.19.10
2025-05-02 23:00:14,394 INFO    MainThread:95126 [wandb_setup.py:_flush():68] Configure stats pid to 95126
2025-05-02 23:00:14,394 INFO    MainThread:95126 [wandb_setup.py:_flush():68] Loading settings from /Users/preddy/.config/wandb/settings
2025-05-02 23:00:14,394 INFO    MainThread:95126 [wandb_setup.py:_flush():68] Loading settings from /Users/preddy/PycharmProjects/Plant-Disease-Diagnosis/plant-disease-detector/src/wandb/settings
2025-05-02 23:00:14,394 INFO    MainThread:95126 [wandb_setup.py:_flush():68] Loading settings from environment variables
2025-05-02 23:00:14,394 INFO    MainThread:95126 [wandb_init.py:setup_run_log_directory():724] Logging user logs to /Users/preddy/PycharmProjects/Plant-Disease-Diagnosis/plant-disease-detector/src/wandb/run-20250502_230014-7ysn7vap/logs/debug.log
2025-05-02 23:00:14,394 INFO    MainThread:95126 [wandb_init.py:setup_run_log_directory():725] Logging internal logs to /Users/preddy/PycharmProjects/Plant-Disease-Diagnosis/plant-disease-detector/src/wandb/run-20250502_230014-7ysn7vap/logs/debug-internal.log
2025-05-02 23:00:14,394 INFO    MainThread:95126 [wandb_init.py:init():852] calling init triggers
2025-05-02 23:00:14,394 INFO    MainThread:95126 [wandb_init.py:init():857] wandb.init called with sweep_config: {}
config: {'_wandb': {}}
2025-05-02 23:00:14,394 INFO    MainThread:95126 [wandb_init.py:init():893] starting backend
2025-05-02 23:00:14,394 INFO    MainThread:95126 [wandb_init.py:init():897] sending inform_init request
2025-05-02 23:00:14,428 INFO    MainThread:95126 [backend.py:_multiprocessing_setup():101] multiprocessing start_methods=spawn,fork,forkserver, using: spawn
2025-05-02 23:00:14,428 INFO    MainThread:95126 [wandb_init.py:init():907] backend started and connected
2025-05-02 23:00:14,433 INFO    MainThread:95126 [wandb_init.py:init():1002] updated telemetry
2025-05-02 23:00:14,473 INFO    MainThread:95126 [wandb_init.py:init():1026] communicating run to backend with 90.0 second timeout
2025-05-02 23:00:14,858 INFO    MainThread:95126 [wandb_init.py:init():1101] starting run threads in backend
2025-05-02 23:00:14,968 INFO    MainThread:95126 [wandb_run.py:_console_start():2566] atexit reg
2025-05-02 23:00:14,968 INFO    MainThread:95126 [wandb_run.py:_redirect():2414] redirect: wrap_raw
2025-05-02 23:00:14,969 INFO    MainThread:95126 [wandb_run.py:_redirect():2483] Wrapping output streams.
2025-05-02 23:00:14,969 INFO    MainThread:95126 [wandb_run.py:_redirect():2506] Redirects installed.
2025-05-02 23:00:14,971 INFO    MainThread:95126 [wandb_init.py:init():1147] run started, returning control to user process
2025-05-02 23:01:05,202 WARNING MsgRouterThr:95126 [router.py:message_loop():63] [no run ID] message_loop has been closed
Traceback (most recent call last):
  File "/Users/preddy/PyCharmMiscProject/.venv2/lib/python3.12/site-packages/wandb/sdk/interface/router_sock.py", line 27, in _read_message
    return self._sock_client.read_server_response(timeout=1)
           ^^^^^^^^^^^^^^^^^^^^^^^^^^^^^^^^^^^^^^^^^^^^^^^^^
  File "/Users/preddy/PyCharmMiscProject/.venv2/lib/python3.12/site-packages/wandb/sdk/lib/sock_client.py", line 235, in read_server_response
    data = self._read_packet_bytes(timeout=timeout)
           ^^^^^^^^^^^^^^^^^^^^^^^^^^^^^^^^^^^^^^^^
  File "/Users/preddy/PyCharmMiscProject/.venv2/lib/python3.12/site-packages/wandb/sdk/lib/sock_client.py", line 220, in _read_packet_bytes
    raise SockClientClosedError
wandb.sdk.lib.sock_client.SockClientClosedError

The above exception was the direct cause of the following exception:

Traceback (most recent call last):
  File "/Users/preddy/PyCharmMiscProject/.venv2/lib/python3.12/site-packages/wandb/sdk/interface/router.py", line 56, in message_loop
    msg = self._read_message()
          ^^^^^^^^^^^^^^^^^^^^
  File "/Users/preddy/PyCharmMiscProject/.venv2/lib/python3.12/site-packages/wandb/sdk/interface/router_sock.py", line 29, in _read_message
    raise MessageRouterClosedError from e
wandb.sdk.interface.router.MessageRouterClosedError
2025-05-02 23:01:05,210 INFO    MsgRouterThr:95126 [mailbox.py:close():129] [no run ID] Closing mailbox, abandoning 1 handles.
2025-05-02 23:01:06,945 ERROR   MainThread:95126 [redirect.py:_on_write():664] [no run ID] error in stderr callback
Traceback (most recent call last):
  File "/Users/preddy/PyCharmMiscProject/.venv2/lib/python3.12/site-packages/tqdm/std.py", line 1182, in __iter__
    yield obj
GeneratorExit

During handling of the above exception, another exception occurred:

Traceback (most recent call last):
  File "/Users/preddy/PyCharmMiscProject/.venv2/lib/python3.12/site-packages/wandb/sdk/lib/redirect.py", line 662, in _on_write
    cb(written_data)
  File "/Users/preddy/PyCharmMiscProject/.venv2/lib/python3.12/site-packages/wandb/sdk/wandb_run.py", line 2493, in <lambda>
    lambda data: self._console_raw_callback("stderr", data),
                 ^^^^^^^^^^^^^^^^^^^^^^^^^^^^^^^^^^^^^^^^^^
  File "/Users/preddy/PyCharmMiscProject/.venv2/lib/python3.12/site-packages/wandb/sdk/wandb_run.py", line 406, in wrapper
    return func(self, *args, **kwargs)
           ^^^^^^^^^^^^^^^^^^^^^^^^^^^
  File "/Users/preddy/PyCharmMiscProject/.venv2/lib/python3.12/site-packages/wandb/sdk/wandb_run.py", line 464, in wrapper_fn
    return func(self, *args, **kwargs)
           ^^^^^^^^^^^^^^^^^^^^^^^^^^^
  File "/Users/preddy/PyCharmMiscProject/.venv2/lib/python3.12/site-packages/wandb/sdk/wandb_run.py", line 1632, in _console_raw_callback
    self._backend.interface.publish_output_raw(name, data)
  File "/Users/preddy/PyCharmMiscProject/.venv2/lib/python3.12/site-packages/wandb/sdk/interface/interface.py", line 763, in publish_output_raw
    self._publish_output_raw(o)
  File "/Users/preddy/PyCharmMiscProject/.venv2/lib/python3.12/site-packages/wandb/sdk/interface/interface_shared.py", line 38, in _publish_output_raw
    self._publish(rec)
  File "/Users/preddy/PyCharmMiscProject/.venv2/lib/python3.12/site-packages/wandb/sdk/interface/interface_sock.py", line 39, in _publish
    self._sock_client.send_record_publish(record)
  File "/Users/preddy/PyCharmMiscProject/.venv2/lib/python3.12/site-packages/wandb/sdk/lib/sock_client.py", line 174, in send_record_publish
    self.send_server_request(server_req)
  File "/Users/preddy/PyCharmMiscProject/.venv2/lib/python3.12/site-packages/wandb/sdk/lib/sock_client.py", line 154, in send_server_request
    self._send_message(msg)
  File "/Users/preddy/PyCharmMiscProject/.venv2/lib/python3.12/site-packages/wandb/sdk/lib/sock_client.py", line 151, in _send_message
    self._sendall_with_error_handle(header + data)
  File "/Users/preddy/PyCharmMiscProject/.venv2/lib/python3.12/site-packages/wandb/sdk/lib/sock_client.py", line 130, in _sendall_with_error_handle
    sent = self._sock.send(data)
           ^^^^^^^^^^^^^^^^^^^^^
BrokenPipeError: [Errno 32] Broken pipe
2025-05-02 23:01:06,949 ERROR   MainThread:95126 [redirect.py:_on_write():664] [no run ID] error in stderr callback
Traceback (most recent call last):
  File "/Users/preddy/PyCharmMiscProject/.venv2/lib/python3.12/site-packages/tqdm/std.py", line 1182, in __iter__
    yield obj
GeneratorExit

During handling of the above exception, another exception occurred:

Traceback (most recent call last):
  File "/Users/preddy/PyCharmMiscProject/.venv2/lib/python3.12/site-packages/wandb/sdk/lib/redirect.py", line 662, in _on_write
    cb(written_data)
  File "/Users/preddy/PyCharmMiscProject/.venv2/lib/python3.12/site-packages/wandb/sdk/wandb_run.py", line 2493, in <lambda>
    lambda data: self._console_raw_callback("stderr", data),
                 ^^^^^^^^^^^^^^^^^^^^^^^^^^^^^^^^^^^^^^^^^^
  File "/Users/preddy/PyCharmMiscProject/.venv2/lib/python3.12/site-packages/wandb/sdk/wandb_run.py", line 406, in wrapper
    return func(self, *args, **kwargs)
           ^^^^^^^^^^^^^^^^^^^^^^^^^^^
  File "/Users/preddy/PyCharmMiscProject/.venv2/lib/python3.12/site-packages/wandb/sdk/wandb_run.py", line 464, in wrapper_fn
    return func(self, *args, **kwargs)
           ^^^^^^^^^^^^^^^^^^^^^^^^^^^
  File "/Users/preddy/PyCharmMiscProject/.venv2/lib/python3.12/site-packages/wandb/sdk/wandb_run.py", line 1632, in _console_raw_callback
    self._backend.interface.publish_output_raw(name, data)
  File "/Users/preddy/PyCharmMiscProject/.venv2/lib/python3.12/site-packages/wandb/sdk/interface/interface.py", line 763, in publish_output_raw
    self._publish_output_raw(o)
  File "/Users/preddy/PyCharmMiscProject/.venv2/lib/python3.12/site-packages/wandb/sdk/interface/interface_shared.py", line 38, in _publish_output_raw
    self._publish(rec)
  File "/Users/preddy/PyCharmMiscProject/.venv2/lib/python3.12/site-packages/wandb/sdk/interface/interface_sock.py", line 39, in _publish
    self._sock_client.send_record_publish(record)
  File "/Users/preddy/PyCharmMiscProject/.venv2/lib/python3.12/site-packages/wandb/sdk/lib/sock_client.py", line 174, in send_record_publish
    self.send_server_request(server_req)
  File "/Users/preddy/PyCharmMiscProject/.venv2/lib/python3.12/site-packages/wandb/sdk/lib/sock_client.py", line 154, in send_server_request
    self._send_message(msg)
  File "/Users/preddy/PyCharmMiscProject/.venv2/lib/python3.12/site-packages/wandb/sdk/lib/sock_client.py", line 151, in _send_message
    self._sendall_with_error_handle(header + data)
  File "/Users/preddy/PyCharmMiscProject/.venv2/lib/python3.12/site-packages/wandb/sdk/lib/sock_client.py", line 130, in _sendall_with_error_handle
    sent = self._sock.send(data)
           ^^^^^^^^^^^^^^^^^^^^^
BrokenPipeError: [Errno 32] Broken pipe
